<?xml version='1.0'?>
<robot name="shady">
	<!-- Base Link -->
	<link name="base_link">
		<visual>
			<origin xyz="0 0 0" rpy="0 0 0" />
			<geometry>
				<box size="0.8 0.5 0.25"/>
			</geometry>
			<material name="blue">
				<color rgba="0 0.7 1 1"/>
			</material>
		</visual>
		<!-- Base collision -->
		<collision>
			<origin xyz="0 0 0" rpy="0 0 0" />
			<geometry>
				<box size="0.8 0.5 0.25"/>
			</geometry>
		</collision>
		<!-- Caster -->
		<visual name="caster">
		<origin xyz="0.3 0 -0.125" rpy="0 0 0" />
		<geometry>
			<sphere radius="0.065" />
		</geometry>
		</visual>
		<!-- Caster collision -->
		<collision>
			<origin xyz="0.3 0 -0.125" rpy="0 0 0" />
			<geometry>
			<sphere radius="0.065" />
			</geometry>
		</collision>
	</link>
	
	<!-- Right Wheel -->
	<link name="right_wheel">
		<visual>
			<origin xyz="0 0 0" rpy="1.570795 0 0" />
			<geometry>
				<cylinder length="0.1" radius="0.15" />
			</geometry>
			<material name="black">
				<color rgba="0.05 0.05 0.05 1"/>
			</material>
		</visual>
	</link>
	<joint name="joint_right_wheel" type="continuous">
		<parent link="base_link"/>
		<child link="right_wheel"/>
		<origin xyz="-0.3 -0.30 -0.07" rpy="0 0 0" />
		<axis xyz="0 1 0" />
	</joint>
	<!-- Right Wheel collision -->
	<collision>
		<origin xyz="0 0 0" rpy="1.570795 0 0" />
		<geometry>
			<cylinder length="0.1" radius="0.15" />
		</geometry>
	</collision>
	<!-- Left Wheel -->
	<link name="left_wheel">
		<visual>
		<origin xyz="0 0 0" rpy="1.570795 0 0" />
		<geometry>
			<cylinder length="0.1" radius="0.15" />
		</geometry>
		<material name="black"/>
		</visual>
	</link>
	<joint name="joint_left_wheel" type="continuous">
		<parent link="base_link"/>
		<child link="left_wheel"/>
		<origin xyz="-0.3 0.30 -0.07" rpy="0 0 0" />
		<axis xyz="0 1 0" />
	</joint>
	<collision>
		<origin xyz="0 0 0" rpy="1.570795 0 0" />
		<geometry>
			<cylinder length="0.1" radius="0.15" />
		</geometry>
	</collision>
</robot>
